Workbook

Sheet 企业分析总览
A1: 岗位信息 v4 · 企业维度分析 | P1: 产业链层级 | Q1: 岗位数 | S1: 公司所属地区 | T1: 岗位数 | V1: 融资轮次 | W1: 岗位数 | Y1: 总部城市 | Z1: 岗位数 | AB1: 重点企业简称 | AC1: 岗位数 | AD1: 企业库标准名称 | AE1: 企业属性字段 | AF1: 完整率
A2: 企业属性以《具身智能企业数据_整合去重_完整.xlsx》为主数据；未匹配项留空，不以模型猜测补齐。统计口径：4,655条v4岗位事实。 | P2: 中游 | Q2: =COUNTIF(岗位信息v4_企业增强!$P$2:$P$4656,P2) -> 2925 | S2: 华东 | T2: =COUNTIF(岗位信息v4_企业增强!$S$2:$S$4656,S2) -> 1808 | V2: 已上市 | W2: =COUNTIF(岗位信息v4_企业增强!$R$2:$R$4656,V2) -> 2499 | Y2: 广东省深圳市南山区 | Z2: =COUNTIF(岗位信息v4_企业增强!$T$2:$T$4656,Y2) -> 791 | AB2: 蓝思科技 | AC2: =COUNTIF(岗位信息v4_企业增强!$AK$2:$AK$4656,AD2) -> 762 | AD2: 蓝思科技股份有限公司 | AE2: 产业链层级 | AF2: =COUNTIF(岗位信息v4_企业增强!$P$2:$P$4656,"<>")/COUNTA(岗位信息v4_企业增强!$B$2:$B$4656) -> 1
P3: 上游 | Q3: =COUNTIF(岗位信息v4_企业增强!$P$2:$P$4656,P3) -> 1156 | S3: 华南 | T3: =COUNTIF(岗位信息v4_企业增强!$S$2:$S$4656,S3) -> 955 | V3: C轮 | W3: =COUNTIF(岗位信息v4_企业增强!$R$2:$R$4656,V3) -> 645 | Y3: 湖南省长沙市浏阳永安园区 | Z3: =COUNTIF(岗位信息v4_企业增强!$T$2:$T$4656,Y3) -> 762 | AB3: 智元创新科技 | AC3: =COUNTIF(岗位信息v4_企业增强!$AK$2:$AK$4656,AD3) -> 567 | AD3: 智元创新（上海）科技股份有限公司 | AE3: 公司细分领域 | AF3: =COUNTIF(岗位信息v4_企业增强!$Q$2:$Q$4656,"<>")/COUNTA(岗位信息v4_企业增强!$B$2:$B$4656) -> 1
A4: 岗位事实 | D4: 企业库已匹配岗位 | G4: 岗位匹配覆盖率 | J4: 已关联企业实体 | M4: 待核验/待补全岗位 | P4: 横向支撑 | Q4: =COUNTIF(岗位信息v4_企业增强!$P$2:$P$4656,P4) -> 287 | S4: 华中 | T4: =COUNTIF(岗位信息v4_企业增强!$S$2:$S$4656,S4) -> 768 | V4: A轮 | W4: =COUNTIF(岗位信息v4_企业增强!$R$2:$R$4656,V4) -> 496 | Y4: 上海市临港新片区 | Z4: =COUNTIF(岗位信息v4_企业增强!$T$2:$T$4656,Y4) -> 567 | AB4: 优必选科技 | AC4: =COUNTIF(岗位信息v4_企业增强!$AK$2:$AK$4656,AD4) -> 457 | AD4: 深圳市优必选科技股份有限公司 | AE4: 融资轮次 | AF4: =COUNTIF(岗位信息v4_企业增强!$R$2:$R$4656,"<>")/COUNTA(岗位信息v4_企业增强!$B$2:$B$4656) -> 1
A5: =COUNTA(岗位信息v4_企业增强!$B$2:$B$4656) -> 4655 | D5: =COUNTIF(岗位信息v4_企业增强!$AN$2:$AN$4656,"已匹配") -> 4472 | G5: =D5/A5 -> 0.96068743 | J5: =COUNTIF(企业岗位汇总!$B$2:$B$634,">0") -> 103 | M5: =A5-D5 -> 183 | P5: 下游 | Q5: =COUNTIF(岗位信息v4_企业增强!$P$2:$P$4656,P5) -> 104 | S5: 华北 | T5: =COUNTIF(岗位信息v4_企业增强!$S$2:$S$4656,S5) -> 368 | V5: B轮 | W5: =COUNTIF(岗位信息v4_企业增强!$R$2:$R$4656,V5) -> 400 | Y5: 江苏省苏州市吴中区 | Z5: =COUNTIF(岗位信息v4_企业增强!$T$2:$T$4656,Y5) -> 388 | AB5: 追觅 | AC5: =COUNTIF(岗位信息v4_企业增强!$AK$2:$AK$4656,AD5) -> 386 | AD5: 追觅科技（苏州）有限公司 | AE5: 公司所属地区 | AF5: =COUNTIF(岗位信息v4_企业增强!$S$2:$S$4656,"<>")/COUNTA(岗位信息v4_企业增强!$B$2:$B$4656) -> 1
S6: 西南 | T6: =COUNTIF(岗位信息v4_企业增强!$S$2:$S$4656,S6) -> 265 | V6: 天使轮/种子轮 | W6: =COUNTIF(岗位信息v4_企业增强!$R$2:$R$4656,V6) -> 189 | Y6: 北京市海淀区 | Z6: =COUNTIF(岗位信息v4_企业增强!$T$2:$T$4656,Y6) -> 347 | AB6: 惠科 | AC6: =COUNTIF(岗位信息v4_企业增强!$AK$2:$AK$4656,AD6) -> 265 | AD6: 惠科股份有限公司 | AE6: 公司总部城市 | AF6: =COUNTIF(岗位信息v4_企业增强!$T$2:$T$4656,"<>")/COUNTA(岗位信息v4_企业增强!$B$2:$B$4656) -> 1
S7: 海外 | T7: =COUNTIF(岗位信息v4_企业增强!$S$2:$S$4656,S7) -> 156 | V7: 央企/国企/事业单位 | W7: =COUNTIF(岗位信息v4_企业增强!$R$2:$R$4656,V7) -> 162 | Y7: 重庆市巴南区 | Z7: =COUNTIF(岗位信息v4_企业增强!$T$2:$T$4656,Y7) -> 265 | AB7: 上海禾赛 | AC7: =COUNTIF(岗位信息v4_企业增强!$AK$2:$AK$4656,AD7) -> 255 | AD7: 上海禾赛科技有限公司
A8: 一眼读懂：v4岗位事实 → 企业名称治理 → 企业库唯一实体 → 产业链/细分领域/融资/地区/总部城市 → 岗位簇与人岗匹配。精确或人工确认别名直接使用；唯一包含匹配标记为中置信；多候选与未匹配项进入待办表。 | S8: 东北 | T8: =COUNTIF(岗位信息v4_企业增强!$S$2:$S$4656,S8) -> 149 | V8: 拟上市/Pre-IPO | W8: =COUNTIF(岗位信息v4_企业增强!$R$2:$R$4656,V8) -> 44 | Y8: 上海市嘉定区 | Z8: =COUNTIF(岗位信息v4_企业增强!$T$2:$T$4656,Y8) -> 255 | AB8: 宇树科技 | AC8: =COUNTIF(岗位信息v4_企业增强!$AK$2:$AK$4656,AD8) -> 172 | AD8: 宇树科技股份有限公司
S9: 港澳台 | T9: =COUNTIF(岗位信息v4_企业增强!$S$2:$S$4656,S9) -> 3 | V9: D轮及以上 | W9: =COUNTIF(岗位信息v4_企业增强!$R$2:$R$4656,V9) -> 26 | Y9: 浙江省杭州市滨江区 | Z9: =COUNTIF(岗位信息v4_企业增强!$T$2:$T$4656,Y9) -> 216 | AB9: 北京清微智能科技 | AC9: =COUNTIF(岗位信息v4_企业增强!$AK$2:$AK$4656,AD9) -> 158 | AD9: 北京清微智能科技股份有限公司
V10: 未融资/未公开 | W10: =COUNTIF(岗位信息v4_企业增强!$R$2:$R$4656,V10) -> 7 | Y10: 吉林省长春市北湖科技开发区 | Z10: =COUNTIF(岗位信息v4_企业增强!$T$2:$T$4656,Y10) -> 149 | AB10: 吉翼具身智能机器人 | AC10: =COUNTIF(岗位信息v4_企业增强!$AK$2:$AK$4656,AD10) -> 149 | AD10: 吉林省吉翼具身智能机器人有限公司
V11: 未披露 | W11: =COUNTIF(岗位信息v4_企业增强!$R$2:$R$4656,V11) -> 2 | Y11: 浙江省杭州市西湖区 | Z11: =COUNTIF(岗位信息v4_企业增强!$T$2:$T$4656,Y11) -> 109 | AB11: 自变量科技 | AC11: =COUNTIF(岗位信息v4_企业增强!$AK$2:$AK$4656,AD11) -> 112 | AD11: 自变量科技（深圳）股份有限公司
V12: 不适用(美的集团控制 | W12: =COUNTIF(岗位信息v4_企业增强!$R$2:$R$4656,V12) -> 1 | Y12: 广东省深圳市前海深港合作区 | Z12: =COUNTIF(岗位信息v4_企业增强!$T$2:$T$4656,Y12) -> 100
V13: D轮 | W13: =COUNTIF(岗位信息v4_企业增强!$R$2:$R$4656,V13) -> 1 | Y13: 浙江省杭州市余杭区 | Z13: =COUNTIF(岗位信息v4_企业增强!$T$2:$T$4656,Y13) -> 99
A49: 职业方向 × 产业链层级：岗位需求落点
A51: 职业方向 | B51: 中游 | C51: 上游 | D51: 横向支撑 | E51: 下游 | H51: 企业库关联结论：当前4,655条岗位中，4,472条已关联企业库，覆盖率96.1%；共关联102个企业实体。未匹配与多候选数据未强行赋值，均进入“企业待补全”。
A52: 基础理论与前沿研究 | B52: =COUNTIFS(岗位信息v4_企业增强!$N$2:$N$4656,$A52,岗位信息v4_企业增强!$P$2:$P$4656,B$51) -> 83 | C52: =COUNTIFS(岗位信息v4_企业增强!$N$2:$N$4656,$A52,岗位信息v4_企业增强!$P$2:$P$4656,C$51) -> 31 | D52: =COUNTIFS(岗位信息v4_企业增强!$N$2:$N$4656,$A52,岗位信息v4_企业增强!$P$2:$P$4656,D$51) -> 6 | E52: =COUNTIFS(岗位信息v4_企业增强!$N$2:$N$4656,$A52,岗位信息v4_企业增强!$P$2:$P$4656,E$51) -> 1
A53: 仿真测试与数据工程 | B53: =COUNTIFS(岗位信息v4_企业增强!$N$2:$N$4656,$A53,岗位信息v4_企业增强!$P$2:$P$4656,B$51) -> 160 | C53: =COUNTIFS(岗位信息v4_企业增强!$N$2:$N$4656,$A53,岗位信息v4_企业增强!$P$2:$P$4656,C$51) -> 38 | D53: =COUNTIFS(岗位信息v4_企业增强!$N$2:$N$4656,$A53,岗位信息v4_企业增强!$P$2:$P$4656,D$51) -> 67 | E53: =COUNTIFS(岗位信息v4_企业增强!$N$2:$N$4656,$A53,岗位信息v4_企业增强!$P$2:$P$4656,E$51) -> 7
A54: 软件硬件与系统架构 | B54: =COUNTIFS(岗位信息v4_企业增强!$N$2:$N$4656,$A54,岗位信息v4_企业增强!$P$2:$P$4656,B$51) -> 1171 | C54: =COUNTIFS(岗位信息v4_企业增强!$N$2:$N$4656,$A54,岗位信息v4_企业增强!$P$2:$P$4656,C$51) -> 885 | D54: =COUNTIFS(岗位信息v4_企业增强!$N$2:$N$4656,$A54,岗位信息v4_企业增强!$P$2:$P$4656,D$51) -> 69 | E54: =COUNTIFS(岗位信息v4_企业增强!$N$2:$N$4656,$A54,岗位信息v4_企业增强!$P$2:$P$4656,E$51) -> 19
A55: 感知决策与控制算法 | B55: =COUNTIFS(岗位信息v4_企业增强!$N$2:$N$4656,$A55,岗位信息v4_企业增强!$P$2:$P$4656,B$51) -> 1117 | C55: =COUNTIFS(岗位信息v4_企业增强!$N$2:$N$4656,$A55,岗位信息v4_企业增强!$P$2:$P$4656,C$51) -> 142 | D55: =COUNTIFS(岗位信息v4_企业增强!$N$2:$N$4656,$A55,岗位信息v4_企业增强!$P$2:$P$4656,D$51) -> 28 | E55: =COUNTIFS(岗位信息v4_企业增强!$N$2:$N$4656,$A55,岗位信息v4_企业增强!$P$2:$P$4656,E$51) -> 53
A56: 部署运维与技术支持 | B56: =COUNTIFS(岗位信息v4_企业增强!$N$2:$N$4656,$A56,岗位信息v4_企业增强!$P$2:$P$4656,B$51) -> 214 | C56: =COUNTIFS(岗位信息v4_企业增强!$N$2:$N$4656,$A56,岗位信息v4_企业增强!$P$2:$P$4656,C$51) -> 34 | D56: =COUNTIFS(岗位信息v4_企业增强!$N$2:$N$4656,$A56,岗位信息v4_企业增强!$P$2:$P$4656,D$51) -> 81 | E56: =COUNTIFS(岗位信息v4_企业增强!$N$2:$N$4656,$A56,岗位信息v4_企业增强!$P$2:$P$4656,E$51) -> 15
A57: 产业支撑与运营 | B57: =COUNTIFS(岗位信息v4_企业增强!$N$2:$N$4656,$A57,岗位信息v4_企业增强!$P$2:$P$4656,B$51) -> 180 | C57: =COUNTIFS(岗位信息v4_企业增强!$N$2:$N$4656,$A57,岗位信息v4_企业增强!$P$2:$P$4656,C$51) -> 26 | D57: =COUNTIFS(岗位信息v4_企业增强!$N$2:$N$4656,$A57,岗位信息v4_企业增强!$P$2:$P$4656,D$51) -> 36 | E57: =COUNTIFS(岗位信息v4_企业增强!$N$2:$N$4656,$A57,岗位信息v4_企业增强!$P$2:$P$4656,E$51) -> 9

Sheet 岗位信息v4_企业增强
A1: 序号 | B1: occ_id | C1: group_id | D1: 公司 | E1: 关联公司 | F1: 岗位 | G1: 城市 | H1: 薪资 | I1: 学历(原始) | J1: 学历(标准化) | K1: 经验(原始) | L1: 经验(标准化) | M1: 能力等级 | N1: 职业方向 | O1: 职业种类 | P1: 产业链层级 | Q1: 公司细分领域 | R1: 融资轮次 | S1: 公司所属地区 | T1: 公司总部城市 | U1: 技能标签 | V1: 清洗JD描述 | W1: 链接 | X1: 发布时间 | Y1: 收录时间 | Z1: 来源列表 | AA1: 是否有有效JD | AB1: 数据来源批次 | AC1: 原始occ_id | AD1: 原始职业方向 | AE1: 原始职业种类 | AF1: 分类方式 | AG1: 分类置信度 | AH1: 发布状态 | AI1: 去重指纹 | AJ1: 处理说明 | AK1: 企业库标准名称 | AL1: 企业匹配方式 | AM1: 企业匹配置信度 | AN1: 企业属性补全状态 | AO1: 产业链12类 | AP1: 融资阶段(企业库原文) | AQ1: 企业库官网 | AR1: 企业库数据来源 | AS1: v4原产业链层级 | AT1: v4原公司细分领域 | AU1: v4原融资轮次 | AV1: v4原公司所属地区 | AW1: v4原公司总部城市
A2: 1 | B2: O00015 | C2: 6027 | D2: Google DeepMind | E2: Google DeepMind | F2: Staff AI Product Designer, Gemini Assistant, GeminiApp | J2: 未说明 | L2: 未说明 | M2: 高级 | N2: 基础理论与前沿研究 | O2: 基础与前沿研究 | P2: 中游 | Q2: 具身智能基础模型/VLA模型/机器人AI大脑 | R2: 央企/国企/事业单位 | S2: 海外 | T2: 美国 加利福尼亚州 山景城 | U2: 机器学习; 多模态; 嵌入式开发; CAN | V2: The Gemini App Design team is instrumental in building the Gemini Universal Assistant, the conversational AI that people around the world use to collaborate with generative AI to fuel their imagination, expand their curiosity, and enhance their productivity. We're building innovative ways for people to get things done & enrich their lives. Our Design team is dedicated to developing the world's useful generative AI experiences. At Google DeepMind, we aim to unlock state-of-the-art artificial intelligence capabilities across Alphabet, creating positive impact and magical product experiences for billions of users. We're a world-leading AI research company, pushing the boundaries of what's possible with artificial intelligence. Our groundbreaking research spans areas like machine learning, neuroscience, and systems engineering, with applications ranging from scientific discovery to creating more helpful and intuitive products. We're committed to developing AI responsibly and ethically, and we foster a collaborative and inclusive environment where brilliant minds come together to tackle some of the world's most challenging problems. Join us and be part of a team that's shaping the future of AI. The Integrated Assistance team contributes towards this mission by making Gemini a personalized universal assistant that is natively present across devices and apps. We unlock useful generative AI experiences through deep OS and app integrations, including the quick access Android overlay, embedded app entry points, and novel screen context capabilities. As shepherds of the largest volume surfaces in Gemini, we aim to guide users to understand the value of generative AI, including unique capabilities outside of the full screen Gemini app. We are a global team with designers based in Europe and US, and engineering and product partners in those locations as well as India. We partner closely with other UX designers in the Gemini App team, including research and modelling. Role We are seeking a highly experienced, self-starting, and innovative Staff AI Product Designer to join our Gemini Integrated Assistance Team. As a key member of our team, you will work hand-in-hand with engineers, research scientists, and product managers to design and build intuitive solutions to help people around the world use Google’s best AI models to enrich their lives and realize their potential. You will play a crucial role in shaping the future of how people interact with AI. You will be involved in all aspects of the design process, from conceptualization and ideation to prototyping and implementation in a fast-moving and highly collaborative environment. Responsibilities: Architect intuitive AI experiences: Lead the design of user interfaces and consumer experiences for Gemini across diverse platforms and modalities, ensuring natural and efficient interaction. Contribute to product strategy and manage stakeholders: Use strong communication skills to collaborate with Product, Engineering and influence relevant stakeholders (e.g. in Gemini App, Android, other Google Apps) to define product strategy and influence key cross-functional decisions that drive positive user outcomes. Innovate through user-centered design: Translate user needs, technical understanding and business requirements into groundbreaking design solutions that amplify people’s capabilities and enrich their lives. Design with systems-thinking approach: Apply a systems-thinking approach to design user interfaces, understanding the impact of individual components and features on the overall AI-powered experience, optimized for AI's probabilistic nature and multimodal capabilities. Craft visually compelling interfaces: Create high-fidelity visual designs, encompassing layouts, typography, color palettes, and iconography, that are aesthetically pleasing and highly usable. Motion and interaction design: Design engaging interactions and fluid interfaces, utilizing tools like Origami Studio, Principle, and Protopie, and create motion designs that enhance user experience and effectively communicate complex information. Bridge design and technology: Leverage technical understanding to use system instructions and diverse prototyping methods, simulating model responses to inform design requirements and approaches. Champion design innovation: Stay current on the latest design trends and technologies, in consumer technology, generative AI and natural language processing, and leverage this knowledge to innovate. Design for ethical and societal impact: Consider the intricate interplay of AI models, user interface, ethical considerations, and societal impacts to develop responsible solutions. Minimum Qualifications Bachelor's degree in Design, Human-Computer Interaction, or a related field. 7+ years of experience designing user interfaces for complex software applications, with specific experience designing for conversational AI / LLMs A robust portfolio showcasing fluency in visual, motion, and interaction design skills, with specific examples of work specific to AI-powered interfaces and interactions and for leading consumer applications. Proficiency in designing user-centric experiences across diverse platforms (web, desktop, mobile), with a strong understanding of how to adapt AI interactions to different device contexts. Demonstrated expertise in designing intuitive and engaging interactions for AI-driven products Demonstrated expertise in guiding cross-functional teams through ideation, validation, and iteration processes, transforming abstract ideas into shippable product Familiarity with behavioral data and strong capability to create data-driven designs, while being equally capable of moving forward in the absence of data. Proficiency in design tools such as Figma, Sketch, Adobe Creative Suite, and Principle. Excellent communication and collaboration skills with the ability to listen, articulate positions, and challenge partners with new product design thinking Mastery in presentation and storytelling capabilities with the ability to communicate effectively to leadership and cross company teams A strong systems thinker with a passion for creating innovative and user-centered AI design solutions. Ability to understand the broader implications of AI technologies and design experiences that are ethical, accessible, and impactful. Demonstrated experience thriving in a startup environment, comfortable with the ambiguity, rapid iteration, and resourcefulness required to deliver impactful designs in a fast-paced, evolving landscape. Preferred Qualifications Demonstrated ability to foster divergent design thinking and translate complex AI concepts into user-centered product visions. Proven experience in shepherding radical ideas that leverage AI to create truly transformative product experiences. Experience prototyping interactive experiences using tools like Figma, ProtoPie, or Framer. Experience vibe-coding with tools like Loveable, ReplitFigmaMake, AI Studio, Cursor or AntiGravity. Experience with front-end development technologies (HTML, CSS, JavaScript, React, Swift, Jetpack Compose) and coding tools (CLIs, IDEs). Demonstrable experience designing polished, highly performant mobile apps and experiences requiring OS integrations (Android, iOS). Experience driving product impact through close collaboration with user research, including expertise in user research methodologies for AI product evaluation. The US base salary range for this full-time position is between $178,000 USD - $265,000 + bonus + equity + benefits. Your recruiter can share more about the specific salary range for your targeted location during the hiring process. Application deadline: Note: In the event your application is successful and an offer of employment is made to you, any offer of employment will be conditional on the results of a background check, performed by a third party acting on our behalf. For more information on how we handle your data, please see our Applicant and Candidate Privacy Policy At Google DeepMind, we value diversity of experience, knowledge, backgrounds and perspectives and harness these qualities to create extraordinary impact. We are committed to equal employment opportunity regardless of sex, race, religion or belief, ethnic or national origin, disability, age, citizenship, marital, domestic or civil partnership status, sexual orientation, gender identity, pregnancy, or related condition (including breastfeeding) or any other basis as protected by applicable law. If you have a disability or additional need that requires accommodation, please do not hesitate to let us know. Create a Job AlertInterested in building your career at DeepMind? Get future opportunities sent straight to your email.Create alert | W2: https://job-boards.greenhouse.io/deepmind/jobs/7762107 | Z2: all_jobs_jd | AA2: 是 | AB2: 核心基线3718 | AC2: O00015 | AD2: 基础理论与前沿研究 | AE2: 基础与前沿研究 | AF2: 原始6方向/17种类标签 | AG2: 高 | AH2: 正式基线 | AI2: 0514c40b8f556477dd38 | AJ2: 核心基线标签直接沿用 | AK2: Google DeepMind Technologies Limited | AL2: 企业别名精确匹配 | AM2: 高 | AN2: 已匹配 | AO2: AI大模型 | AP2: 央企/国企；Alphabet内部（未独立融资） | AQ2: https://deepmind.google | AR2: Google DeepMind官网/TechSpot/The Robot Report | AS2: 中游-AI基础模型（具身大脑） | AT2: 具身智能基础模型/VLA模型/机器人AI大脑 | AU2: 央企/国企/事业单位 | AV2: 海外 | AW2: 美国加利福尼亚州山景城(Mountain View, CA); 英国伦敦
A3: 2 | B3: O00014 | C3: 6022 | D3: Google DeepMind | E3: Google DeepMind | F3: Staff AI Product Designer, Gemini Assistant | J3: 未说明 | L3: 未说明 | M3: 中级 | N3: 基础理论与前沿研究 | O3: 基础与前沿研究 | P3: 中游 | Q3: 具身智能基础模型/VLA模型/机器人AI大脑 | R3: 央企/国企/事业单位 | S3: 海外 | T3: 美国 加利福尼亚州 山景城 | U3: 机器学习; 多模态; CAN | V3: The Gemini App Design team is instrumental in building the Gemini Universal Assistant, the conversational AI that people around the world use to collaborate with generative AI to fuel their imagination, expand their curiosity, and enhance their productivity. We're building innovative ways for people to get things done & enrich their lives. Our Design team is dedicated to developing the world's useful generative AI experiences. At Google DeepMind, we aim to unlock state-of-the-art artificial intelligence capabilities across Alphabet, creating positive impact and magical product experiences for billions of users. We're a world-leading AI research company, pushing the boundaries of what's possible with artificial intelligence. Our groundbreaking research spans areas like machine learning, neuroscience, and systems engineering, with applications ranging from scientific discovery to creating more helpful and intuitive products. We're committed to developing AI responsibly and ethically, and we foster a collaborative and inclusive environment where brilliant minds come together to tackle some of the world's most challenging problems. Join us and be part of a team that's shaping the future of AI.Role We are seeking a highly experienced, self-starting, and innovative Senior AI Product Designer to join the Gemini App Team. As a key member of our team, you will work hand-in-hand with engineers, research scientists, and product managers to design and build intuitive solutions to help people around the world use Google’s best AI models to enrich their lives and realize their potential. You will play a crucial role in shaping the future of how people interact with AI. You will be involved in all aspects of the design process, from conceptualization and ideation to prototyping and implementation in a fast-moving and highly collaborative environment. Responsibilities: Architect intuitive AI experiences: Lead the design of user interfaces and consumer experiences for Gemini across diverse platforms and modalities, ensuring natural and efficient interaction. Key contributor to product strategy: Collaborate with Product and Engineering to define product strategy and influence key cross-functional decisions that drive positive user outcomes. Innovate through user-centered design: Translate user needs, technical understanding and business requirements into groundbreaking design solutions that amplify people’s capabilities and enrich their lives. Design with systems-thinking approach: Apply a systems-thinking approach to design user interfaces, understanding the impact of individual components and features on the overall AI-powered experience, optimized for AI's probabilistic nature and multimodal capabilities. Craft visually compelling interfaces: Create high-fidelity visual designs, encompassing layouts, typography, color palettes, and iconography, that are aesthetically pleasing and highly usable. Motion and interaction design: Design engaging interactions and fluid interfaces, utilizing tools like Origami Studio, Principle, and Protopie, and create motion designs that enhance user experience and effectively communicate complex information. Bridge design and technology: Leverage technical understanding to use system instructions and diverse prototyping methods, simulating model responses to inform design requirements and approaches. Champion design innovation: Stay current on the latest design trends and technologies, in consumer technology, generative AI and natural language processing, and leverage this knowledge to innovate. Design for ethical and societal impact: Consider the intricate interplay of AI models, user interface, ethical considerations, and societal impacts to develop responsible solutions. Minimum Qualifications Bachelor's degree in Design, Human-Computer Interaction, or a related field. 7+ years of experience designing user interfaces for complex software applications, with specific experience designing for conversational AI / LLMs A robust portfolio showcasing fluency in visual, motion, and interaction design skills, with specific examples of work specific to AI-powered interfaces and interactions and for leading consumer applications. Proficiency in designing user-centric experiences across diverse platforms (web, desktop, mobile), with a strong understanding of how to adapt AI interactions to different device contexts. Demonstrated expertise in designing intuitive and engaging interactions for AI-driven products Demonstrated expertise in guiding cross-functional teams through ideation, validation, and iteration processes, transforming abstract ideas into shippable product Familiarity with behavioral data and strong capability to create data-driven designs, while being equally capable of moving forward in the absence of data. Proficiency in design tools such as Figma, Sketch, Adobe Creative Suite, and Principle. Excellent communication and collaboration skills with the ability to listen, articulate positions, and challenge partners with new product design thinking Mastery in presentation and storytelling capabilities with the ability to communicate effectively to leadership and cross company teams A strong systems thinker with a passion for creating innovative and user-centered AI design solutions. Ability to understand the broader implications of AI technologies and design experiences that are ethical, accessible, and impactful. Demonstrated experience thriving in a startup environment, comfortable with the ambiguity, rapid iteration, and resourcefulness required to deliver impactful designs in a fast-paced, evolving landscape. Preferred Qualifications Demonstrated ability to foster divergent design thinking and translate complex AI concepts into user-centered product visions. Proven experience in shepherding radical ideas that leverage AI to create truly transformative product experiences. Experience prototyping interactive experiences using tools like Figma, ProtoPie, or Framer. Experience with front-end development technologies (HTML, CSS, JavaScript). Experience driving product impact through close collaboration with user research, including expertise in user research methodologies for AI product evaluation. Experience mentoring more junior teammates, but note this is not a manager role The US base salary range for this full-time position is between $178,000 USD - $265,000 + bonus + equity + benefits. Your recruiter can share more about the specific salary range for your targeted location during the hiring process. Application deadline: Note: In the event your application is successful and an offer of employment is made to you, any offer of employment will be conditional on the results of a background check, performed by a third party acting on our behalf. For more information on how we handle your data, please see our Applicant and Candidate Privacy Policy At Google DeepMind, we value diversity of experience, knowledge, backgrounds and perspectives and harness these qualities to create extraordinary impact. We are committed to equal employment opportunity regardless of sex, race, religion or belief, ethnic or national origin, disability, age, citizenship, marital, domestic or civil partnership status, sexual orientation, gender identity, pregnancy, or related condition (including breastfeeding) or any other basis as protected by applicable law. If you have a disability or additional need that requires accommodation, please do not hesitate to let us know.Create a Job AlertInterested in building your career at DeepMind? Get future opportunities sent straight to your email.Create alert | W3: https://job-boards.greenhouse.io/deepmind/jobs/7561947 | Z3: all_jobs_jd | AA3: 是 | AB3: 核心基线3718 | AC3: O00014 | AD3: 基础理论与前沿研究 | AE3: 基础与前沿研究 | AF3: 原始6方向/17种类标签 | AG3: 高 | AH3: 正式基线 | AI3: 444d925042f718d5fb79 | AJ3: 核心基线标签直接沿用 | AK3: Google DeepMind Technologies Limited | AL3: 企业别名精确匹配 | AM3: 高 | AN3: 已匹配 | AO3: AI大模型 | AP3: 央企/国企；Alphabet内部（未独立融资） | AQ3: https://deepmind.google | AR3: Google DeepMind官网/TechSpot/The Robot Report | AS3: 中游-AI基础模型（具身大脑） | AT3: 具身智能基础模型/VLA模型/机器人AI大脑 | AU3: 央企/国企/事业单位 | AV3: 海外 | AW3: 美国加利福尼亚州山景城(Mountain View, CA); 英国伦敦
A4: 3 | B4: O00016 | C4: 6026 | D4: Google DeepMind | E4: Google DeepMind | F4: Staff AI Product Designer, Growth & Discovery, GeminiApp | J4: 未说明 | L4: 未说明 | M4: 高级 | N4: 基础理论与前沿研究 | O4: 基础与前沿研究 | P4: 中游 | Q4: 具身智能基础模型/VLA模型/机器人AI大脑 | R4: 央企/国企/事业单位 | S4: 海外 | T4: 美国 加利福尼亚州 山景城 | U4: 机器学习; 多模态; CAN | V4: At Google DeepMind, we aim to unlock state-of-the-art artificial intelligence capabilities across Alphabet, creating positive impact and magical product experiences for billions of users. We're a world-leading AI research company, pushing the boundaries of what's possible with artificial intelligence. Our groundbreaking research spans areas like machine learning, neuroscience, and systems engineering, with applications ranging from scientific discovery to creating more helpful and intuitive products. We're committed to developing AI responsibly and ethically, and we foster a collaborative and inclusive environment where brilliant minds come together to tackle some of the world's most challenging problems. Join us and be part of a team that's shaping the future of AI.Role We are seeking a highly experienced, self-starting, and innovative Staff AI Product Designer focusing on our Growth and Discovery initiatives. As a key member of our team, you will work hand-in-hand with engineers, research scientists, and product managers to design and build intuitive solutions to help people around the world use Google’s best AI models to enrich their lives and realize their potential. You will play a crucial role in shaping the future of how people interact with AI. You will be involved in all aspects of the design process, from conceptualization and ideation to prototyping and implementation in a fast-moving and highly collaborative environment. Responsibilities: Architect intuitive AI experiences: Lead the design of user interfaces and consumer experiences for Gemini across diverse platforms and modalities, ensuring natural and efficient interaction. Key contributor to product strategy: Collaborate with Product and Engineering to define product strategy and influence key cross-functional decisions that drive positive user outcomes. Innovate through user-centered design: Translate user needs, technical understanding and business requirements into groundbreaking design solutions that amplify people’s capabilities and enrich their lives. Design with systems-thinking approach: Apply a systems-thinking approach to design user interfaces, understanding the impact of individual components and features on the overall AI-powered experience, optimized for AI's probabilistic nature and multimodal capabilities. Craft visually compelling interfaces: Create high-fidelity visual designs, encompassing layouts, typography, color palettes, and iconography, that are aesthetically pleasing and highly usable. Motion and interaction design: Design engaging interactions and fluid interfaces, utilizing tools like Origami Studio, Principle, and Protopie, and create motion designs that enhance user experience and effectively communicate complex information. Bridge design and technology: Leverage technical understanding to use system instructions and diverse prototyping methods, simulating model responses to inform design requirements and approaches. Champion design innovation: Stay current on the latest design trends and technologies, in consumer technology, generative AI and natural language processing, and leverage this knowledge to innovate. Design for ethical and societal impact: Consider the intricate interplay of AI models, user interface, ethical considerations, and societal impacts to develop responsible solutions. Minimum Qualifications Bachelor's degree in Design, Human-Computer Interaction, or a related field. 7+ years of experience designing user interfaces for complex software applications, with specific experience designing for conversational AI / LLMs A robust portfolio showcasing fluency in visual, motion, and interaction design skills, with specific examples of work specific to AI-powered interfaces and interactions and for leading consumer applications. Proficiency in designing user-centric experiences across diverse platforms (web, desktop, mobile), with a strong understanding of how to adapt AI interactions to different device contexts. Demonstrated expertise in designing intuitive and engaging interactions for AI-driven products Demonstrated expertise in guiding cross-functional teams through ideation, validation, and iteration processes, transforming abstract ideas into shippable product Familiarity with behavioral data and strong capability to create data-driven designs, while being equally capable of moving forward in the absence of data. Proficiency in design tools such as Figma, Sketch, Adobe Creative Suite, and Principle. Excellent communication and collaboration skills with the ability to listen, articulate positions, and challenge partners with new product design thinking Mastery in presentation and storytelling capabilities with the ability to communicate effectively to leadership and cross company teams A strong systems thinker with a passion for creating innovative and user-centered AI design solutions. Ability to understand the broader implications of AI technologies and design experiences that are ethical, accessible, and impactful. Demonstrated experience thriving in a startup environment, comfortable with the ambiguity, rapid iteration, and resourcefulness required to deliver impactful designs in a fast-paced, evolving landscape. Preferred Qualifications Demonstrated ability to foster divergent design thinking and translate complex AI concepts into user-centered product visions. Proven experience in shepherding radical ideas that leverage AI to create truly transformative product experiences. Experience prototyping interactive experiences using tools like Figma, ProtoPie, or Framer. Experience with front-end development technologies (HTML, CSS, JavaScript). Experience driving product impact through close collaboration with user research, including expertise in user research methodologies for AI product evaluation. The US base salary range for this full-time position is between $178,000 USD - $265,000 + bonus + equity + benefits. Your recruiter can share more about the specific salary range for your targeted location during the hiring process. Application deadline: Note: In the event your application is successful and an offer of employment is made to you, any offer of employment will be conditional on the results of a background check, performed by a third party acting on our behalf. For more information on how we handle your data, please see our Applicant and Candidate Privacy Policy At Google DeepMind, we value diversity of experience, knowledge, backgrounds and perspectives and harness these qualities to create extraordinary impact. We are committed to equal employment opportunity regardless of sex, race, religion or belief, ethnic or national origin, disability, age, citizenship, marital, domestic or civil partnership status, sexual orientation, gender identity, pregnancy, or related condition (including breastfeeding) or any other basis as protected by applicable law. If you have a disability or additional need that requires accommodation, please do not hesitate to let us know.Create a Job AlertInterested in building your career at DeepMind? Get future opportunities sent straight to your email.Create alert | W4: https://job-boards.greenhouse.io/deepmind/jobs/7728122 | Z4: all_jobs_jd | AA4: 是 | AB4: 核心基线3718 | AC4: O00016 | AD4: 基础理论与前沿研究 | AE4: 基础与前沿研究 | AF4: 原始6方向/17种类标签 | AG4: 高 | AH4: 正式基线 | AI4: 22c635254556cae53728 | AJ4: 核心基线标签直接沿用 | AK4: Google DeepMind Technologies Limited | AL4: 企业别名精确匹配 | AM4: 高 | AN4: 已匹配 | AO4: AI大模型 | AP4: 央企/国企；Alphabet内部（未独立融资） | AQ4: https://deepmind.google | AR4: Google DeepMind官网/TechSpot/The Robot Report | AS4: 中游-AI基础模型（具身大脑） | AT4: 具身智能基础模型/VLA模型/机器人AI大脑 | AU4: 央企/国企/事业单位 | AV4: 海外 | AW4: 美国加利福尼亚州山景城(Mountain View, CA); 英国伦敦
A5: 4 | B5: O00012 | C5: 6025 | D5: Google DeepMind | E5: Google DeepMind | F5: Research Scientist, Multimodal Alignment, Safety, and Fairness | J5: 未说明 | L5: 未说明 | M5: 中级 | N5: 基础理论与前沿研究 | O5: 基础与前沿研究 | P5: 中游 | Q5: 具身智能基础模型/VLA模型/机器人AI大脑 | R5: 央企/国企/事业单位 | S5: 海外 | T5: 美国 加利福尼亚州 山景城 | U5: Python; JAX; 强化学习; 深度学习; 机器学习; 计算机视觉; 多模态; CAN; Prompt Engineering | V5: We are seeking strong Research Scientists with expertise in AI research and experience in interdisciplinary sociotechnical modeling to join a multimodal safety research effort within Google DeepMind's Frontier AI unit. This role requires a passion for understanding and modeling the interactions between AI and society, a strong awareness of the AI alignment and safety landscape, and a penchant for developing novel ideas, methods, interfaces, and tools. This is a unique opportunity to contribute to impactful research and advance Google DeepMind's mission towards Artificial General Intelligence (AGI). About us Artificial Intelligence could be one of humanity’s most useful inventions. At Google DeepMind, we’re a team of scientists, engineers, machine learning experts and more, working together to advance the state of the art in artificial intelligence and ultimately achieve Artificial General Intelligence. We use our technologies for widespread public benefit and scientific discovery, and collaborate with others on critical challenges, ensuring safety and ethics are the highest priority. We’re a dedicated scientific community, committed to “solving intelligence” and ensuring our technology is used for widespread public benefit. We’ve built a supportive and inclusive environment where collaboration is encouraged and learning is shared freely. We don’t set limits based on what others think is possible or impossible. We drive ourselves and inspire each other to push boundaries and achieve ambitious goals. Our team is a part of Google DeepMind's Frontier AI unit. We have a mission to advance the frontiers of safety and inclusion in multimodal AI, build new capabilities into Google's flagship models and products, and break new ground on AI alignment. We approach alignment research with an ecosystem view, partnering across the development and deployment cycle and grounding our work in real-world impact on global users and communities. We are a research team with a mandate to invest in longer term bets and explore innovative approaches that deliver breakthrough improvements to models (Gemini) and products. Our work is at the frontier of augmented oversight for multimodal AI, and our research advances have directly impacted multiple versions of Gemini and Nano Banana models. The role We are seeking strong Research Scientists with expertise in AI research and experience in interdisciplinary sociotechnical modeling, to lead new breakthrough research directions. You will join a team working to supercharge exploration, assessment, and steering of evolving AI behaviors, with a focus on subjective and creative tasks. You will tackle the underlying research questions to improve collaborative specification of alignment objectives and assessment of adherence to desired behaviors. You will research new methods to enable AI agents to monitor real-world social context and dynamically evaluate and evolve system behaviors over long time-horizons. You’ll develop new paradigms for human+AI rating that considers systemic behaviors, adapts to human feedback, and proactively seeks context. Research Scientists at Google DeepMind lead the development of novel tools and algorithms to solve Artificial General Intelligence. Joining from top academic or industrial labs, they collaborate across fields to tackle fundamental AI questions using expertise in deep learning, computer vision, and generative architectures. This role requires independent judgment to navigate complex, ambiguous problems and explore diverse technical avenues. Your work will drive breakthroughs within GDM, Google products, and the AI alignment community. Key responsibilities Research: Generate new ideas, keep up with the state of the art in the field, discuss research directions with other researchers. Execute: Design, rapidly implement, and rigorously evaluate cutting-edge ideas, methods, interfaces, and tools to explore new sociotechnical AI systems. Communicate: Report and present research findings and developments clearly and efficiently both internally and externally, verbally and in writing. Collaborate: Suggest and engage in inter- and intra- team collaborations to meet ambitious research goals, while also driving significant individual contributions. Drive technical projects: Take ownership of substantial technical projects, from ideation and design to implementation and evaluation, often involving cross-functional collaboration. About you In order to set you up for success as a Research Scientist at Google DeepMind, we look for the following skills and experience: Requirements: PhD degree in Computer Science, Machine Learning, or a related technical field. Strong publication record in top machine learning conferences (e.g., NeurIPS, CVPR, ICML, ICLR, ICCV, ECCV). Demonstrated hands-on experience in developing multimodal AI models and systems, Strong programming skills in Python and experience with at least one major deep learning framework (e.g., JAX/Flax/Gemax) Experience conducting independent research and development, including experimental design, implementation, and analysis. In addition, the following would be an advantage: Proven expertise in working with and tuning large-scale vision language models. Experience prototyping with VLMs with modern prompting strategies Experience finetuning and post-training LLMs using RL Experience with developing agentic AI solutions to complex problems Excited to collaborate across orgs and disciplines to leverage diverse perspectives and expertise and find creative solutions. Interest and a strong awareness of the AI alignment / safety / responsibility / fairness landscape Experience with Generative AI techniques and architectures. Familiarity with Reinforcement Learning or alignment methods. Experience with multimodal learning, integrating information from different data types (e.g., vision, audio, text). The US base salary range for this full-time position is between 147,000 USD - 211,000 USD + bonus + equity + benefits. Your recruiter can share more about the specific salary range for your targeted location during the hiring process. Note: In the event your application is successful and an offer of employment is made to you, any offer of employment will be conditional on the results of a background check, performed by a third party acting on our behalf. For more information on how we handle your data, please see our Applicant and Candidate Privacy Policy. At Google DeepMind, we value diversity of experience, knowledge, backgrounds and perspectives and harness these qualities to create extraordinary impact. We are committed to equal employment opportunities regardless of sex, race, religion or belief, ethnic or national origin, disability, age, citizenship, marital, domestic or civil partnership status, sexual orientation, gender identity, pregnancy, or related condition (including breastfeeding) or any other basis as protected by applicable law. If you have a disability or additional need that requires accommodation, please do not hesitate to let us know.Create a Job AlertInterested in building your career at DeepMind? Get future opportunities sent straight to your email.Create alert | W5: https://job-boards.greenhouse.io/deepmind/jobs/7680885 | Z5: all_jobs_jd | AA5: 是 | AB5: 核心基线3718 | AC5: O00012 | AD5: 基础理论与前沿研究 | AE5: 基础与前沿研究 | AF5: 原始6方向/17种类标签 | AG5: 高 | AH5: 正式基线 | AI5: 74b2bdafc78c6e83202a | AJ5: 核心基线标签直接沿用 | AK5: Google DeepMind Technologies Limited | AL5: 企业别名精确匹配 | AM5: 高 | AN5: 已匹配 | AO5: AI大模型 | AP5: 央企/国企；Alphabet内部（未独立融资） | AQ5: https://deepmind.google | AR5: Google DeepMind官网/TechSpot/The Robot Report | AS5: 中游-AI基础模型（具身大脑） | AT5: 具身智能基础模型/VLA模型/机器人AI大脑 | AU5: 央企/国企/事业单位 | AV5: 海外 | AW5: 美国加利福尼亚州山景城(Mountain View, CA); 英国伦敦
A6: 5 | B6: O00018 | C6: 6021 | D6: Google DeepMind | E6: Google DeepMind | F6: Tech Strategy Director, Compute, Google DeepMind | J6: 未说明 | L6: 未说明 | M6: 高级 | N6: 基础理论与前沿研究 | O6: 基础与前沿研究 | P6: 中游 | Q6: 具身智能基础模型/VLA模型/机器人AI大脑 | R6: 央企/国企/事业单位 | S6: 海外 | T6: 美国 加利福尼亚州 山景城 | U6: 机器学习; 动力学; CAN | V6: This is a critical and high impact strategic role that will drive AI strategy, infrastructure investments and AI product portfolio optimization across Google. The role sits within Google DeepMind’s Technology Strategy (TechStrat) function and is a leadership role within Techstrat’s Compute team. Since compute has become the key ingredient for AI model leadership, AI serving success and next generation AI research, this leader will drive high impact decisions that will define the success of Google, with implications on the future of AI for the world. About us Artificial Intelligence could be one of humanity’s most useful inventions. At Google DeepMind, we’re a team of scientists, engineers, machine learning experts and more, working together to advance the state of the art in artificial intelligence. We use our technologies for widespread public benefit and scientific discovery, and collaborate with others on critical challenges, ensuring safety and ethics are the highest priority. The role As one of the key senior leaders of the compute Tech Strategy team, this role will own the success of our AI strategy by driving the maximal product impact for Google and AI impact for humanity. This leader will have the responsibility of framing key strategic decisions for our SVP+ leadership group based on deep analysis of the situation including value at stake from AI investments, investment optimization options, Industry understanding, financial modeling, product strategy analysis and understanding. They will be constantly looking for opportunities to push the envelope of impact from our investments in AI and inspire the team to do the same. This leader will also drive the synthesis of the situation into SVP+ consumable frameworks and crisp grounded and data backed options. They will then ensure the strategy is executed flawlessly partnering with a multitude of cross functional teams and stakeholders. Key responsibilities Personally drive and amplify impact through leading a team to Investigate and drive clarity on some of Google’s hardest long range strategic questions in AI Create new and partner with existing virtual teams across Google to create comprehensive product and policy plans that stand the test of time Model scenarios and various tradeoffs to create opinionated strategies for maximizing AI value and optimizing AI investments across Google Create SVP+ forum content (presentations, communications, mandates) Help develop a per-mandate monitoring view to keep programs accountable Collaborate with operational teams and forums in AI to ensure that company-wide SVP+mandates are set up for success -- well organized, staffed and delivering on desired goals. Stay connected across Google to maintain a living catalog of ongoing experiments & proposed innovations that may become worthy of discussion at NRC Identify gaps in our processes and information and propose/implement solutions. About you Are you a PM who thrives as both a central hub orchestrating complex and long running investigations AND a rapid iteration IC who can quickly create something out of nothing and move on to the next thing? This is the job for you. In both cases, you must be able to concisely communicate the merits & risks of multiple scenarios in documents that will get circulated broadly and to some of the most senior folks at the company. If you have high energy, a positive attitude, strong tech judgment, excellent interpersonal skills, and are excited to handle complex pan-Google topics and SVP audiences, this job will offer an opportunity to have a massive company-wide impact. In order to set you up for success as a Product Manager at DeepMind, we look for the following skills and experience: BA/BS degree in Computer Science/ EE or equivalent practical experience in a technical and/or business area 15+ years of product management experience for a technology-driven company, at scale, including a proven track record in driving 0->1 product capabilities and founding or incubating new, high-impact technical initiatives. Exceptional organizational talent running high velocity, high impact, strategic programs Stellar verbal and written communication; past experience with SVP/VP+ level audiences Extensive experience in product operations and business strategy Strong analytics, strategy, and data fluency experience Experience in a role that deals with machine learning and/or compute Innovative problem solver that can turn ambiguous problem spaces into clear solutions Ability to influence without direct authority, you adeptly work on and with technical and cross-functional or highly matrixed teams in a way that leads to aligned decision making In addition, the following would be an advantage: Familiarity with the role of compute and data in building LLMs and the capabilities of these models Strong product vision and sensibility, ideally with prior and proven experience embedding applied AI capabilities into products and a track record of leveraging AI productivity tools 5+ years of product strategy work experience in managing highly-complex, technically-challenging projects spanning a wide set of stakeholders A quantitative and analytical mentality to understand Google PA and external user needs Experience navigating sensitive organizational dynamics Collaborating within data-driven or quantitative-focused teams A consistent record of creative problem solving and a bias towards action Outstanding business judgment Outstanding organizational, prioritization, and multitasking skills. Excellent communication skills A proven track record of building positive relationships with senior stakeholders and influencing strong personalities within a complex business environment Experience in corporate planning Ability to manage multiple concurrent complex interactions with geographically disparate teams Past people management experience; Experience in hiring and leading teams, including distributed teams At Google DeepMind, we value diversity of experience, knowledge, backgrounds and perspectives and harness these qualities to create extraordinary impact. We are committed to equal employment opportunities regardless of sex, race, religion or belief, ethnic or national origin, disability, age, citizenship, marital, domestic or civil partnership status, sexual orientation, gender identity, pregnancy, or related condition (including breastfeeding) or any other basis as protected by applicable law. If you have a disability or additional need that requires accommodation, please do not hesitate to let us know. Application deadline: 13th Feb 2026 Note: In the event your application is successful and an offer of employment is made to you, any offer of employment will be conditional on the results of a background check, performed by a third party acting on our behalf. For more information on how we handle your data, please see our Applicant and Candidate Privacy Policy.Create a Job AlertInterested in building your career at DeepMind? Get future opportunities sent straight to your email.Create alert | W6: https://job-boards.greenhouse.io/deepmind/jobs/7535866 | Z6: all_jobs_jd | AA6: 是 | AB6: 核心基线3718 | AC6: O00018 | AD6: 基础理论与前沿研究 | AE6: 基础与前沿研究 | AF6: 原始6方向/17种类标签 | AG6: 高 | AH6: 正式基线 | AI6: 4f25750961905128011c | AJ6: 核心基线标签直接沿用 | AK6: Google DeepMind Technologies Limited | AL6: 企业别名精确匹配 | AM6: 高 | AN6: 已匹配 | AO6: AI大模型 | AP6: 央企/国企；Alphabet内部（未独立融资） | AQ6: https://deepmind.google | AR6: Google DeepMind官网/TechSpot/The Robot Report | AS6: 中游-AI基础模型（具身大脑） | AT6: 具身智能基础模型/VLA模型/机器人AI大脑 | AU6: 央企/国企/事业单位 | AV6: 海外 | AW6: 美国加利福尼亚州山景城(Mountain View, CA); 英国伦敦
A7: 6 | B7: O00019 | C7: 6019 | D7: Google DeepMind | E7: Google DeepMind | F7: Research Engineer, Materials Science | J7: 未说明 | L7: 未说明 | M7: 初级 | N7: 基础理论与前沿研究 | O7: 基础与前沿研究 | P7: 中游 | Q7: 具身智能基础模型/VLA模型/机器人AI大脑 | R7: 央企/国企/事业单位 | S7: 海外 | T7: 美国 加利福尼亚州 山景城 | U7: PyTorch; TensorFlow; JAX; LLM; 深度学习; 机器学习; Diffusion; 动力学; 仿真; 嵌入式开发; CAN | V7: At Google DeepMind, we value diversity of experience, knowledge, backgrounds and perspectives and harness these qualities to create extraordinary impact. We are committed to equal employment opportunities regardless of sex, race, religion or belief, ethnic or national origin, disability, age, citizenship, marital, domestic or civil partnership status, sexual orientation, gender identity, pregnancy or related condition (including breastfeeding) or any other basis as protected by applicable law. If you have a disability or additional need that requires accommodation, please do not hesitate to let us know. Science is at the heart of everything we do at Google DeepMind. From the beginning, we took inspiration from science to build better algorithms, and now, we want to use our toolkit to accelerate scientific discovery. By bringing together specialists with backgrounds in machine learning, computer science, physics, chemistry, biology and more, we’re optimistic that we can build new methods that will push the boundaries of what is possible and help solve the biggest problems facing humanity. Project Overview Google DeepMind (GDM) is pursuing a ground-breaking research program in materials, aiming to accelerate the discovery of new functional materials by combining the predictive power of artificial intelligence (AI) and computational simulation with automated experimentation. You'll join an interdisciplinary team of domain experts, ML researchers, and engineers exploring a diverse set of important scientific problems in materials science, physics, quantum chemistry and other areas. Our work is organised into several longer-term focus areas, which aim to achieve step changes to the state-of-the-art (as exemplified in e.g. DM21 and GNoME). The role To succeed in this role you will need to be passionate about advancing material science using machine learning and other computational techniques. As an embedded Research Engineer you will collaborate with other researchers and engineers to develop infrastructure for running experiments and help researchers explore new applications of AI and LLMs to materials science. The team is pioneering in many different domains so you will take part in exploratory work that enables validating early ideas, and work in a maturing area to deepen and build infrastructure to exploit a promising line of research. You will also contribute to the scientific knowledge and experience of the team with your own scientific domain knowledge. Key responsibilities: Plan and perform rapid prototyping of machine learning techniques applied to problems in science. Undertake exploratory analysis to inform experimentation and research directions. Make improvements to model architectures and training procedures of machine learning models. Implement tools, libraries and frameworks to speed up and enable new research. Report and present software developments, experimental results and data analysis clearly and efficiently. Collaborate with internal and external scientific domain experts. About you Research Engineers come from a diverse set of backgrounds, sometimes with degrees in Computer Science and sometimes with extensive experience with real problems, or both. In order to set you up for success as a Research Engineer at Google DeepMind, we look for the following skills and experience: Degree in computer science, electrical engineering, science, mathematics or equivalent experience. Experience applying software engineering principles in a scientific research environment. Knowledge of linear algebra, calculus and statistics equivalent to at least first-year university coursework. Experience exploring, analysing, and visualising large and noisy datasets. Experience using Jax, PyTorch, TensorFlow, NumPy, Pandas or similar ML/scientific libraries. In addition, we also look for at least one of the following: Specific domain expertise in areas like inorganic chemistry, solid-state physics, or materials synthesis. Experience applying modern deep learning architectures (e.g., transformers, diffusion models) to chemistry or material science challenges (e.g. ML force fields). Experience running large-scale scientific simulations (e.g. molecular dynamics, computational chemistry simulations, etc.) on Cloud or HPC clusters. Experience developing custom LLM agents or tool-using systems. Experience with concurrent and distributed software algorithms and architectures. Masters or PhD in computer science, electrical engineering, science, mathematics or equivalent experience. The US base salary range for this full-time position is between $141,000 - $202,000 + bonus + equity + benefits. Your recruiter can share more about the specific salary range for your targeted location during the hiring process. Note: In the event your application is successful and an offer of employment is made to you, any offer of employment will be conditional on the results of a background check, performed by a third party acting on our behalf. For more information on how we handle your data, please see our Applicant and Candidate Privacy Policy At Google DeepMind, we value diversity of experience, knowledge, backgrounds and perspectives and harness these qualities to create extraordinary impact. We are committed to equal employment opportunity regardless of sex, race, religion or belief, ethnic or national origin, disability, age, citizenship, marital, domestic or civil partnership status, sexual orientation, gender identity, pregnancy, or related condition (including breastfeeding) or any other basis as protected by applicable law. If you have a disability or additional need that requires accommodation, please do not hesitate to let us know. Create a Job AlertInterested in building your career at DeepMind? Get future opportunities sent straight to your email.Create alert | W7: https://job-boards.greenhouse.io/deepmind/jobs/7339890 | Z7: all_jobs_jd | AA7: 是 | AB7: 核心基线3718 | AC7: O00019 | AD7: 基础理论与前沿研究 | AE7: 基础与前沿研究 | AF7: 原始6方向/17种类标签 | AG7: 高 | AH7: 正式基线 | AI7: c03d8b693d28b1b93518 | AJ7: 核心基线标签直接沿用 | AK7: Google DeepMind Technologies Limited | AL7: 企业别名精确匹配 | AM7: 高 | AN7: 已匹配 | AO7: AI大模型 | AP7: 央企/国企；Alphabet内部（未独立融资） | AQ7: https://deepmind.google | AR7: Google DeepMind官网/TechSpot/The Robot Report | AS7: 中游-AI基础模型（具身大脑） | AT7: 具身智能基础模型/VLA模型/机器人AI大脑 | AU7: 央企/国企/事业单位 | AV7: 海外 | AW7: 美国加利福尼亚州山景城(Mountain View, CA); 英国伦敦
